Workbook

Sheet Proveedores
B2: Proveedor | G2: Observación: Usar estos nombres de proveedores para completar las planillas
B3: Acerco | C3: Cba | D3: Hierro
B4: Serin | C4: Cba | D4: Hierro
B5: Acero VCA S.A.S | C5: Alta gracia | D5: Hierros
B6: Almada | C6: Cba | D6: Obra gruesa | E6: cuenta corriente
B7: Alquilo BV | C7: Cba | D7: Alquiler maquinaria | E7: cuenta corriente
B8: Alquilo Todo | C8: Cba | D8: Alquiler maquinaria | E8: cuenta corriente
B9: Alquilo Todo AG | C9: Cba | D9: Alquiler maquinaria
B10: Alquilo Todo VGB | C10: Cba | D10: Alquiler maquinaria | E10: cuenta corriente
B11: Apromax | C11: Cba | D11: Obra gruesa
B12: Boccolini | C12: Cba | D12: Áridos
B13: Boderau | C13: Cba | D13: Áridos
B14: San Cayetano | C14: Cba | D14: Áridos
B15: Cerroplast | C15: Cba | D15: Media sombra
B16: Calido 20° | C16: Cba | D16: Climatización
B17: Can-Mar | C17: Calamuchita | D17: Áridos
B18: Cantera El Alto | C18: Alta gracia | D18: Hormigón
B19: Canteras | C19: Cba | D19: Porcellanato
B20: Chamtac | C20: Cba | D20: Impermeabilización
B21: CM impr. | C21: Cba | D21: Impermeabilización
B22: Enpolex | C22: Cba | D22: Molones
... B24: Prohome - Kevin | C24: Cba | D24: Domótica
B25: Conte Fer | C25: Cba-Mendiolaza | D25: Contenedor obra | L25: Alias: naracha CVU: 0000003100039046325684 Nombre: Matias Nicolas Fiora
B26: Conte Mas | C26: Cba | D26: Contenedor obra
B27: Conte Mas | C27: Cba | D27: Baño quimico
B28: Conte Top | C28: Cba | D28: Contenedor obra | E28: cuenta corriente
B29: Conte Top | C29: Cba | D29: Baño quimico | E29: cuenta corriente
B30: Contigiani | C30: Cba | D30: Obra gruesa | E30: cuenta corriente
B31: Centro Acero | C31: Cba | D31: Hierros
B32: Cristian Canziani | C32: VGB | D32: Fletes
B33: De Stefano | C33: Cba | D33: Porcellanato
B34: Deplano | C34: Cba | D34: Instalaciones | E34: cuenta corriente
B35: Dickhaus | C35: Vgb | D35: Obra gruesa
B36: Dimotec | C36: Cba | D36: Bombas hidrau
B37: Edificor | C37: Cba | D37: Porcellanato
B38: El Alto | C38: Alta gracia | D38: Áridos
B39: Electroalem | C39: Cba | D39: Electricidad | E39: cuenta corriente
B40: Enas | C40: Cba | D40: Alquiler maquinaria | E40: cuenta corriente
B41: Enpolex | C41: Cba | D41: Molones
B42: Hermida | C42: Cba | D42: Separadores
...

Sheet Calendario
B2: Lunes | C2: Martes | D2: Miércoles | E2: Jueves | F2: Viernes | G2: Sábado | H2: Domingo
B3: NOVIEMBRE
E4: 45981 | F4: 45982
B5: 45985 | C5: 45986 | D5: 45987 | E5: 45988 | F5: 45989
L6: Feriados
B7: DICIEMBRE | L7: carga area computo
B8: 45992 | C8: 45993 | D8: 45994 | E8: 45995 | F8: 45996 | G8: 45997 | H8: 45998 | L8: Despues area adm manda pagos
B9: 45999 | C9: 46000 | D9: 46001 | E9: 46002 | F9: 46003 | G9: 46004 | H9: 46005 | L9: Dia de pagos
B10: 46006 | C10: 46007 | D10: 46008 | E10: 46009 | F10: 46010 | G10: 46011 | H10: 46012
B11: 46013 | C11: 46014 | D11: 46015 | E11: 46016 | F11: 46017 | G11: 46018 | H11: 46019 | L11: Todos los jueves se actualiza el tablero
B12: 46020 | C12: 46021 | D12: 46022
B13: 2026
B14: ENERO
E15: 46023 | F15: 46024
B16: 46027 | C16: 46028 | D16: 46029 | E16: 46030 | F16: 46031 | G16: 46032 | H16: 46033
B17: 46034 | C17: 46035 | D17: 46036 | E17: 46037 | F17: 46038 | G17: 46039 | H17: 46040
B18: 46041 | C18: 46042 | D18: 46043 | E18: 46044 | F18: 46045 | G18: 46046 | H18: 46047
B19: 46048 | C19: 46049 | D19: 46050 | E19: 46051 | F19: 46052 | G19: 46053
B20: FEBRERO
H21: 46054
B22: 46055 | C22: 46056 | D22: 46057 | E22: 46058 | F22: 46059 | G22: 46060 | H22: 46061
B23: 46062 | C23: 46063 | D23: 46064 | E23: 46065 | F23: 46066 | G23: 46067 | H23: 46068
B24: 46069 | C24: 46070 | D24: 46071 | E24: 46072 | F24: 46073 | G24: 46074 | H24: 46075
B25: 46076 | C25: 46077 | D25: 46078 | E25: 46079 | F25: 46080 | G25: 46081 | H25: 46082
B26: MARZO
H27: 46082
B28: 46083 | C28: 46084 | D28: 46085 | E28: 46086 | F28: 46087 | G28: 46088 | H28: 46089
B29: 46090 | C29: 46091 | D29: 46092 | E29: 46093 | F29: 46094 | G29: 46095 | H29: 46096
B30: 46097 | C30: 46098 | D30: 46099 | E30: 46100 | F30: 46101 | G30: 46102 | H30: 46103
B31: 46104 | C31: 46105 | D31: 46106 | E31: 46107 | F31: 46108 | G31: 46109 | H31: 46110
B32: 46111 | C32: 46112
B33: ABRIL
D34: 46113 | E34: 46114 | F34: 46115 | G34: 46116 | H34: 46117
B35: 46118 | C35: 46119 | D35: 46120 | E35: 46121 | F35: 46122 | G35: 46123 | H35: 46124
B36: 46125 | C36: 46126 | D36: 46127 | E36: 46128 | F36: 46129 | G36: 46130 | H36: 46131
B37: 46132 | C37: 46133 | D37: 46134 | E37: 46135 | F37: 46136 | G37: 46137 | H37: 46138
B38: 46139 | C38: 46140 | D38: 46141 | E38: 46142
B39: MAYO
F40: 46143 | G40: 46144 | H40: 46145
B41: 46146 | C41: 46147 | D41: 46148 | E41: 46149 | F41: 46150 | G41: 46151 | H41: 46152
...

Sheet Obra SG
D2: GASTOS MATERIAL OBRA
D3: Cliente: | E3: SG
D4: Domicilio: | F4: Localidad:
B9: OBRA | C9: Fecha de FC | D9: Condición | E9: Razón social | F9: Descripción | G9: Proveedor | H9: Rubro | I9: Importe final Pesos (Iva incluido) | J9: Importe final USD (Iva incluido) | K9: Observaciones | L9: Estado Factura Cliente | M9: Estado Factura Bauvek | N9: Estado material | O9: Resarcimiento Bauvek | P9: Nº Remito | Q9: Encargado
B10: =+$E$3 -> SG
B11: =+$E$3 -> SG
B12: =+$E$3 -> SG
B13: =+$E$3 -> SG | C13: 45988 | D13: Fact-A-27083 | E13: Guillermo Fiore | F13: 2 placas antihumedad y perfiles z | G13: Jack | H13: Durlock | I13: 91470.24 | K13: A bauvek | L13: Cuenta Corriente
B14: =+$E$3 -> SG | C14: 45989 | D14: Fact-A-27097 | E14: Guillermo Fiore | F14: 4 placas comunes y 2 puntas atorn. | G14: Jack | H14: Durlock | I14: 58182.63 | K14: A bauvek | L14: Cuenta Corriente
B15: =+$E$3 -> SG | C15: 45988 | D15: Fact-A-08640 | E15: Guillermo Fiore | F15: Materiales de pintura, rodillos y lijas | G15: Garin | H15: Pintura | K15: A proveedor | L15: Pagado
B16: =+$E$3 -> SG | C16: 45996 | D16: Fact-A-27313 | E16: Guillermo Fiore | F16: 1 cinta tramada y 1 lata de masilla | G16: Jack | H16: Durlock | I16: 26266.89 | K16: A bauvek | L16: Cuenta Corriente
B17: =+$E$3 -> SG | C17: 46001 | D17: Efectivo | F17: Flete de tejuelas de Almada a obra SG | G17: Flete Hugo Godoy | H17: Fletes | I17: 57000 | K17: A bauvek | L17: Pagado
B18: =+$E$3 -> SG | C18: 46001 | D18: Efectivo | F18: Devolucion de andamios de obra a Guaticor | G18: Flete Hugo Godoy | H18: Fletes | I18: 57000 | K18: A bauvek | L18: Pagado
B19: =+$E$3 -> SG | C19: 46006 | D19: Efectivo | F19: Una placa vibradora | G19: Alquilo Todo | H19: Alquiler | I19: 60000 | K19: A bauvek | L19: Pagado
B20: =+$E$3 -> SG | C20: 46008 | D20: Efectivo | F20: Flete de pegamento de contigiani y pintura de garin | G20: Flete Hugo Godoy | H20: Fletes | I20: 72000 | K20: A bauvek | L20: Pagado
A21: Pasado quincena | C21: 46022
B22: =+$E$3 -> SG | C22: 46028 | D22: Fact-B-22514 | E22: Guillermo Fiore | F22: Alambre tejido + ganchos + alambre 2.2, etc | G22: Cerco | H22: Terminacion | I22: 85271.19 | K22: A proveedor | L22: Pagado
B23: =+$E$3 -> SG | C23: 46029 | D23: Fact-B-171951 | E23: Guillermo Fiore | F23: Material de plomeria | G23: Saniplast | H23: Plomeria | I23: 465269.3 | K23: A proveedor | L23: Pagado
B24: =+$E$3 -> SG | C24: 46029 | D24: Fact-B-171950 | E24: Guillermo Fiore | F24: Bomba presurizadora | G24: Saniplast | H24: Plomeria | I24: 385891.6 | K24: A proveedor | L24: Pagado
B25: =+$E$3 -> SG | C25: 46031 | D25: Efectivo | E25: Sin Factura | F25: Flete de materiales de CERCO, CONTIGIANI y SANIPLAST a obra | G25: Flete Hugo Godoy | H25: Fletes | I25: 37500 | K25: Pago en efectivo | L25: Pagado
B26: =+$E$3 -> SG | C26: 46031 | D26: Fact-B-140685 | E26: Guillermo Fiore | F26: Bastidores, modulos, teclas, etc. | G26: Feyro | H26: Electricidad | I26: 230000.02 | K26: A proveedor | L26: Pagado
B27: =+$E$3 -> SG | C27: 46031 | D27: Fact-B-140686 | E27: Guillermo Fiore | F27: Cables | G27: Feyro | H27: Electricidad | I27: 380000.3 | K27: A proveedor | L27: Pagado
B28: =+$E$3 -> SG | C28: 46031 | D28: Fact-B-140687 | E28: Guillermo Fiore | F28: 7 Luz led embutido de ingreso | G28: Feyro | H28: Electricidad | I28: 360000.02 | K28: A proveedor | L28: Pagado
B29: =+$E$3 -> SG | C29: 46031 | D29: Fact-B-140688 | E29: Guillermo Fiore | F29: Plafones, lamparas, spots | G29: Feyro | H29: Electricidad | I29: 587500.04 | K29: A proveedor | L29: Pagado
B30: =+$E$3 -> SG | C30: 46034 | D30: Fact-B-14076 | E30: Consumidor final | F30: Tornillos, tarugos y disco videa | G30: Ferreteros | H30: Ferretería | I30: 12214.95 | K30: Pago Mariana de Bauvek, recuperar | L30: Pagado
B31: =+$E$3 -> SG | C31: 46035 | D31: Efectivo | E31: Sin Factura | F31: 1 viaje de tierra negra | G31: Nicolas Carusso | H31: Mov. De suelo | I31: 190000 | K31: A bauvek | L31: Pagado
B32: =+$E$3 -> SG | C32: 46035 | D32: Efectivo | E32: Sin Factura | F32: Flete de materiales de saniplast, retirar hercal y adoquines y llevar a obra arzola | G32: Flete Hugo Godoy | H32: Fletes | I32: 65000 | K32: Pago en efectivo | L32: Pagado
A33: Pasado quincena | C33: 46037
B34: =+$E$3 -> SG | C34: 46038 | D34: Fact-B-00106530 | E34: Consumidor final | F34: Porcelanato de cocina + pastina | G34: Edificor | H34: Revestimiento | I34: 255311.44 | K34: A proveedor | L34: Pagado
B35: =+$E$3 -> SG | C35: 46036 | D35: Efectivo | E35: Sin Factura | F35: Flete de materiales de SANIPLAST a obra | G35: Flete Hugo Godoy | H35: Fletes | I35: 60000 | K35: A bauvek | L35: Pagado
B36: =+$E$3 -> SG | C36: 46043 | D36: Fact-A-27097 | E36: A cuenta bauvek | F36: Travesaños largos | G36: Jack | H36: Durlock | I36: 16506.52 | K36: A bauvek | L36: Pagado
B37: =+$E$3 -> SG | C37: 46044 | D37: NC-A-28345 | E37: A cuenta bauvek | F37: Devolucion Travesaños largos | G37: Jack | H37: Durlock | I37: -16506.52 | K37: A bauvek | L37: Pagado
B38: =+$E$3 -> SG | C38: 46044 | D38: Fact-A-28343 | E38: A cuenta bauvek | F38: Travesaños cortos | G38: Jack | H38: Durlock | I38: 18237.7 | K38: A bauvek | L38: Pagado
A39: Pasado quincena | C39: 46051
A40: Pasado quincena | C40: 46065
A41: Prox cierre | C41: 46093
B42: =+$E$3 -> SG
B43: =+$E$3 -> SG
B44: =+$E$3 -> SG
B45: =+$E$3 -> SG
...

Sheet Obra HR
D2: GASTOS MATERIAL OBRA
D3: Cliente: | E3: Hernan Reboni
D4: Domicilio: | E4: Lote 456 | F4: Localidad: | H4: El Terrón
B9: OBRA | C9: Fecha de FC | D9: Condición | E9: Razón social | F9: Descripción | G9: Proveedor | H9: Rubro | I9: Importe final Pesos (Iva incluido) | J9: Importe final USD (Iva incluido) | K9: Observaciones | L9: Estado Factura Cliente | M9: Estado Factura Bauvek | N9: Estado material | O9: Resarcimiento Bauvek | P9: Nº Remito | Q9: Encargado
B10: =+$E$3 -> Hernan Reboni
A11: Pasado quincena | C11: 46037
B12: =+$E$3 -> Hernan Reboni
B13: =+$E$3 -> Hernan Reboni
B14: =+$E$3 -> Hernan Reboni
B15: =+$E$3 -> Hernan Reboni
B16: =+$E$3 -> Hernan Reboni
B17: =+$E$3 -> Hernan Reboni
B18: =+$E$3 -> Hernan Reboni
B19: =+$E$3 -> Hernan Reboni
B20: =+$E$3 -> Hernan Reboni
B21: =+$E$3 -> Hernan Reboni
B22: =+$E$3 -> Hernan Reboni
B23: =+$E$3 -> Hernan Reboni
... B49: =+$E$3 -> Hernan Reboni
G51: TOTAL | H51: =SUM(I10:I49) -> 0

Sheet Obra FAR
D2: GASTOS MATERIAL OBRA
D3: Cliente: | E3: REMODELACION ARZOLA
D4: Domicilio: | E4: Huascar 8631, Arguello | F4: Localidad: | H4: Arguello
B9: OBRA | C9: Fecha de FC | D9: Condición | E9: Razón social | F9: Descripción | G9: Proveedor | H9: Rubro | I9: Importe final Pesos (Iva incluido) | J9: Importe final USD (Iva incluido) | K9: Observaciones | L9: Estado Factura Cliente | M9: Estado Factura Bauvek | N9: Estado material | O9: Resarcimiento Bauvek | P9: Nº Remito | Q9: Encargado | R9: Columna1 | S9: Columna2
B10: =+$E$3 -> REMODELACION ARZOLA | C10: 45863 | D10: PRES - 24300 | E10: BAUVEK S.A.S. | F10: Materiales de DURLOCK | G10: Jack | H10: Obra Gruesa | I10: =1228234.35 -> 1228234.4 | L10: Pagado | M10: Pagado
B11: =+$E$3 -> REMODELACION ARZOLA | C11: 45860 | D11: FACT 13-6500-A | E11: BAUVEK S.A.S. | F11: Materiales de OBRA GRUESA | G11: Almada | H11: Obra Gruesa | I11: 1086246.8 | L11: Pagado | M11: Pagado
B12: =+$E$3 -> REMODELACION ARZOLA | C12: 45870 | D12: Efectivo | E12: Sin Factura | F12: 1 VIAJE DE ARENA GRUESA Y 1/2 VIAJE DE GRANZA | G12: Nico Carusso | H12: Obra Gruesa | I12: 280000 | L12: Pagado | M12: Pagado
B13: =+$E$3 -> REMODELACION ARZOLA | C13: 45866 | D13: Efectivo | E13: Sin Factura | F13: 1 ROLLO DE GEOMEMBRANA Y 20KG DE ALAMBRE ATAR | G13: Almada | H13: Obra Gruesa | I13: 184187.15 | K13: Material que se llevo del QB | L13: Pagado | M13: Pagado
B14: =+$E$3 -> REMODELACION ARZOLA | C14: 45856 | D14: Efectivo | E14: Sin Factura | F14: 1 PAQUETE DE SOLERAS | G14: Jack | H14: Obra Gruesa | I14: 30223.92 | K14: Material que se llevo del QB | L14: Pagado | M14: Pagado
B15: =+$E$3 -> REMODELACION ARZOLA | C15: 45870 | D15: Efectivo | E15: Sin Factura | F15: EQUIPOS BAJO SILUETA Y SPLIT | G15: Goldman | H15: Calefacción | I15: 6694875.3 | L15: Pagado | M15: Pagado
B16: =+$E$3 -> REMODELACION ARZOLA | C16: 45861 | D16: Efectivo | E16: Sin Factura | F16: CORTAR ARBOLES | G16: Gabriel Bobcat | H16: Limpieza de arboles | I16: 600000 | L16: Pagado | M16: Pagado
B17: =+$E$3 -> REMODELACION ARZOLA | C17: 45863 | D17: PRES - 24583 | E17: BAUVEK S.A.S. | F17: MATERIAL DURLOCK PAREDES Y CIELORASO | G17: Jack | H17: Obra Gruesa | I17: 685091.44 | L17: Pagado | M17: Pagado
B18: =+$E$3 -> REMODELACION ARZOLA | C18: 45881 | D18: Efectivo | E18: Sin Factura | F18: MATERIAL DE OBRA GRUESA PARA AMPLIACION | G18: Almada | H18: Obra Gruesa | I18: 3700000 | L18: Pagado | M18: Pagado
B19: =+$E$3 -> REMODELACION ARZOLA | C19: 45888 | D19: Efectivo | E19: Sin Factura | F19: LADRILLOS PARA AMPLIACION | G19: Almada | H19: Obra Gruesa | I19: 1200000 | L19: Pagado | M19: Pagado
B20: =+$E$3 -> REMODELACION ARZOLA | C20: 45881 | D20: Efectivo | E20: Sin Factura | F20: REVOQUE FINO - 8 BOLSAS | G20: Almada | H20: Obra Gruesa | I20: 49966.44 | L20: Pagado | M20: Pagado
B21: =+$E$3 -> REMODELACION ARZOLA | C21: 45881 | D21: Efectivo | E21: Sin Factura | F21: MATERIALES DE KIT Y CONDUCTOS | G21: Adrian Giordano | H21: Calefacción | I21: 3773588 | L21: Pagado | M21: Pagado
B22: =+$E$3 -> REMODELACION ARZOLA | C22: 45881 | D22: Efectivo | E22: Sin Factura | F22: MANO DE OBRA INSTALCION EQUIPOS | G22: Adrian Giordano | H22: Calefacción | I22: 780000 | L22: Pagado | M22: Pagado
B23: =+$E$3 -> REMODELACION ARZOLA | C23: 45888 | D23: FACT 61575 | E23: BAUVEK S.A.S. | F23: MATERIALES DE ELECTRICIDAD | G23: Feyro | H23: Electricidad | I23: 630433.74 | L23: Pagado | M23: Pagado
B24: =+$E$3 -> REMODELACION ARZOLA | C24: 45888 | D24: NC 24853 | E24: Sin Factura | F24: DEVOLUCIÓN DE UNOS TARUGOS | G24: Jack | H24: Obra Gruesa | I24: -8294 | L24: Pagado | M24: Pagado
B25: =+$E$3 -> REMODELACION ARZOLA | C25: 45888 | D25: Efectivo | E25: Sin Factura | F25: TARUGOS + TORNILLOS FISHER 8mm | G25: Jack | H25: Obra Gruesa | I25: 61470 | L25: Pagado | M25: Pagado
B26: =+$E$3 -> REMODELACION ARZOLA | C26: 45890 | D26: Efectivo | E26: Sin Factura | F26: MATERIAL DE DURLOCK | G26: Jack | H26: Obra Gruesa | I26: 227142.84 | L26: Pagado | M26: Pagado
... B30: =+$E$3 -> REMODELACION ARZOLA | C30: 45902 | D30: Efectivo | E30: Sin Factura | F30: HORMIGÓN DE FUNDACIÓN 4m3 (adicionales/con remito) | G30: Hormiblock | H30: Obra Gruesa | I30: 439200 | L30: Pagado | M30: Pagado
B31: =+$E$3 -> REMODELACION ARZOLA | C31: 45896 | D31: FACT 38416 | E31: BAUVEK S.A.S. | F31: Material de agua | G31: Deplano | H31: Plomeria | I31: 707214.44 | L31: Pagado | M31: Pagado | N31: Recibido en obra
B32: =+$E$3 -> REMODELACION ARZOLA | C32: 45897 | D32: Efectivo | E32: Sin Factura | F32: 1 VIAJE DE ARENA GRUESA | G32: Nico Carusso | H32: Obra Gruesa | I32: 130000 | L32: Pagado | M32: Pagado
B33: =+$E$3 -> REMODELACION ARZOLA | C33: 45898 | D33: Efectivo | E33: Sin Factura | F33: 3 cámaras de seguridad Kit Wifi | G33: Seguridad Centro | H33: Instalaciones | I33: 218500 | L33: Pagado | M33: Pagado
B34: =+$E$3 -> REMODELACION ARZOLA | C34: 45903 | D34: FACT 48252 | E34: BAUVEK S.A.S. | F34: Material de cloaca y pluvial | G34: Deplano | H34: Plomeria | I34: 11897.06 | L34: Pagado | M34: Pagado | N34: Recibido en obra
B35: =+$E$3 -> REMODELACION ARZOLA | C35: 45903 | D35: FACT 48243 | E35: BAUVEK S.A.S. | F35: Material de cloaca y pluvial | G35: Deplano | H35: Plomeria | I35: 40920 | L35: Pagado | M35: Pagado | N35: Recibido en obra
B36: =+$E$3 -> REMODELACION ARZOLA | C36: 45903 | D36: FACT 38526 | E36: BAUVEK S.A.S. | F36: Material de cloaca y pluvial | G36: Deplano | H36: Plomeria | I36: 348461.78 | L36: Pagado | M36: Pagado | N36: Recibido en obra
B37: =+$E$3 -> REMODELACION ARZOLA | C37: 45903 | D37: FACT 38525 | E37: BAUVEK S.A.S. | F37: Material de cloaca y pluvial | G37: Deplano | H37: Plomeria | I37: 239753.93 | L37: Pagado | M37: Pagado | N37: Recibido en obra
B38: =+$E$3 -> REMODELACION ARZOLA | C38: 45904 | D38: Efectivo | E38: Sin Factura | F38: 1/2 VIAJE DE ARENA FINA | G38: Nico Carusso | H38: Obra Gruesa | I38: 160000 | L38: Pagado | M38: Pagado
B39: =+$E$3 -> REMODELACION ARZOLA | C39: 45909 | D39: FACT 9004 | E39: BAUVEK S.A.S. | F39: Rodillo de pintura | G39: Garin | H39: Pintura | I39: 10538.6 | L39: Pagado | M39: Pagado
B40: =+$E$3 -> REMODELACION ARZOLA | C40: 45909 | D40: FACT 62298 | E40: BAUVEK S.A.S. | F40: Materiales electricos | G40: Feyro | H40: Electricidad | I40: 664000.02 | L40: Pagado | M40: Pagado
B41: =+$E$3 -> REMODELACION ARZOLA | C41: 45918 | D41: Efectivo | E41: Sin Factura | F41: 6 palet del portante del 18 | G41: Almada | H41: Obra Gruesa | I41: 671534.8 | L41: Pagado | M41: Pagado
B42: =+$E$3 -> REMODELACION ARZOLA | C42: 45918 | D42: Efectivo | E42: Sin Factura | F42: 1 viaje de arena | G42: Nico Carusso | H42: Aridos | I42: 140000 | L42: Pagado | M42: Pagado
B43: =+$E$3 -> REMODELACION ARZOLA | C43: 45919 | D43: Efectivo | E43: Sin Factura | F43: Materiales para losa | G43: Almada | H43: Obra Gruesa | I43: 2723000 | L43: Pagado | M43: Pagado
B44: =+$E$3 -> REMODELACION ARZOLA | C44: 45930 | D44: Efectivo | E44: Sin Factura | F44: 1 viaje de arena | G44: Nico Carusso | H44: Aridos | I44: 140000 | L44: Pagado | M44: Pagado
B45: =+$E$3 -> REMODELACION ARZOLA | C45: 45943 | D45: Efectivo | E45: Sin Factura | F45: 250 ladrillos comunes | G45: Almada | H45: Obra Gruesa | I45: 52339.83 | L45: Pagado | M45: Pagado
B46: =+$E$3 -> REMODELACION ARZOLA | C46: 45943 | D46: Efectivo | E46: Sin Factura | F46: Hierro y block portante para el cerco | G46: Almada | H46: Obra Gruesa | I46: 3181511.6 | L46: Pagado | M46: Pagado
B47: =+$E$3 -> REMODELACION ARZOLA | C47: 45948 | D47: Efectivo | E47: Sin Factura | F47: 1 viaje de arena | G47: Nico Carusso | H47: Aridos | I47: 140000 | L47: Pagado | M47: Pagado
B48: =+$E$3 -> REMODELACION ARZOLA | C48: 45954 | D48: Efectivo | E48: Sin Factura | F48: 1 viaje de arena | G48: Nico Carusso | H48: Aridos | I48: 140000 | L48: Pagado | M48: Pagado
...

Sheet Obra JS
D2: GASTOS MATERIAL OBRA
D3: Cliente: | E3: JULIETA SANTIAGO - IVAN PETRINI
D4: Domicilio: | E4: MZA 58 - LOTE 10 | F4: Localidad: | H4: Molvento
B9: OBRA | C9: Fecha de FC | D9: Condición | E9: Razón social | F9: Descripción | G9: Proveedor | H9: Rubro | I9: Importe final Pesos (Iva incluido) | J9: Importe final USD (Iva incluido) | K9: Observaciones | L9: Estado Factura Cliente | M9: Estado Factura Bauvek | N9: Estado material | O9: Resarcimiento Bauvek | P9: Nº Remito | Q9: Encargado | R9: Columna1
B10: =+$E$3 -> JULIETA SANTIAGO - IVAN PETRINI | C10: 45734 | D10: Fact-A-23399 | E10: PETRINI IVAN | F10: Puntales de pino para cerco | G10: Mendio | H10: Obra Preliminar | I10: 295210.23 | K10: A proveedor | L10: Pagado | M10: Pagado | N10: Recibido en obra
B11: =+$E$3 -> JULIETA SANTIAGO - IVAN PETRINI | C11: 45733 | D11: Fact-A-12403 | E11: PETRINI IVAN | F11: Media sombra para cerco | G11: Cerroplast | H11: Obra Preliminar | I11: 247755.37 | K11: A proveedor | L11: Pagado | M11: Pagado | N11: Recibido en obra
B12: =+$E$3 -> JULIETA SANTIAGO - IVAN PETRINI | C12: 45751 | D12: Fact-A-283011 | E12: PETRINI IVAN | F12: Material de hierro | G12: Serin | H12: Obra Gruesa | I12: 18176362 | K12: A proveedor | L12: Pagado | M12: Pagado | N12: Recibido en obra
B13: =+$E$3 -> JULIETA SANTIAGO - IVAN PETRINI | C13: 45751 | D13: Fact-A-158348 | E13: PETRINI IVAN | F13: Material de hierro - alambres y clavos | G13: Serin | H13: Obra Gruesa | I13: 895017.35 | K13: A proveedor | L13: Pagado | M13: Pagado | N13: Recibido en obra
B14: =+$E$3 -> JULIETA SANTIAGO - IVAN PETRINI | C14: 45758 | D14: Fact-A-158599 | E14: PETRINI IVAN | F14: Material para porton | G14: Serin | H14: Obra Gruesa | I14: 222592.8 | K14: A proveedor | L14: Pagado | M14: Pagado | N14: Recibido en obra
B15: =+$E$3 -> JULIETA SANTIAGO - IVAN PETRINI | C15: 45772 | D15: Efectivo | E15: Sin factura | F15: Obrador y baño quimico x 6 meses | G15: Natalia Obrador | H15: Obra Gruesa | I15: 1100000 | K15: A bauvek | L15: Pagado | M15: Pagado | N15: Recibido en obra
B16: =+$E$3 -> JULIETA SANTIAGO - IVAN PETRINI | C16: 45792 | G16: Mendio | I16: 622770 | K16: A bauvek | L16: Pagado | M16: Pagado | N16: Recibido en obra
B17: =+$E$3 -> JULIETA SANTIAGO - IVAN PETRINI | C17: 45800 | D17: Efectivo | E17: Sin factura | F17: Hormigon de fundaciones pilotes | G17: Hormiblock | H17: Obra Gruesa | I17: 8960000 | K17: A bauvek | L17: Pagado | M17: Pagado | N17: Recibido en obra
B18: =+$E$3 -> JULIETA SANTIAGO - IVAN PETRINI | C18: 45821 | H18: Obra Gruesa | I18: 3480000 | K18: A bauvek | L18: Pagado | M18: Pagado
B19: =+$E$3 -> JULIETA SANTIAGO - IVAN PETRINI | C19: 45825 | D19: Efectivo | E19: Sin factura | F19: Hormigon de vigas de fundacion | G19: Hormiblock | H19: Obra Gruesa | I19: 6305000 | K19: A bauvek | L19: Pagado | M19: Pagado | N19: Recibido en obra
B20: =+$E$3 -> JULIETA SANTIAGO - IVAN PETRINI | C20: 45825 | D20: Efectivo | E20: Sin factura | F20: Tablas cepilladas, fenolicos, etc | G20: Mendio | H20: Obra Gruesa | I20: 5900970 | K20: A bauvek | L20: Pagado | M20: Pagado | N20: Recibido en obra
B21: =+$E$3 -> JULIETA SANTIAGO - IVAN PETRINI | C21: 45825 | D21: Efectivo | E21: Sin factura | F21: Planchuelas para columnas | G21: Roncaglia | H21: Obra Metalica | I21: 73000 | K21: A bauvek | L21: Pagado | M21: Pagado | N21: Recibido en obra
B22: =+$E$3 -> JULIETA SANTIAGO - IVAN PETRINI | C22: 45831 | D22: Fact-A-286400 | E22: PETRINI IVAN | F22: 28 hierro del 16 | G22: Serin | H22: Obra Gruesa | I22: 907493.44 | K22: A proveedor | L22: Pagado | M22: Pagado | N22: Recibido en obra
B23: =+$E$3 -> JULIETA SANTIAGO - IVAN PETRINI | C23: 45831 | D23: Fact-A-286401 | E23: PETRINI IVAN | F23: 100 mallas | G23: Serin | H23: Obra Gruesa | I23: 1327719.7 | K23: A proveedor | L23: Pagado | M23: Pagado | N23: Recibido en obra
B24: =+$E$3 -> JULIETA SANTIAGO - IVAN PETRINI | C24: 45859 | D24: Fact-A- | E24: PETRINI IVAN | F24: Material de obra gruesa (facturado) | G24: Apromax | H24: Obra Gruesa | I24: 12500000 | K24: A proveedor | L24: Pagado | M24: Pagado | N24: Recibido en obra
B25: =+$E$3 -> JULIETA SANTIAGO - IVAN PETRINI | C25: 45859 | D25: Efectivo | E25: PETRINI IVAN | F25: Material de obra gruesa (en efectivo) | G25: Apromax | H25: Obra Gruesa | I25: 12598800 | K25: A proveedor | L25: Pagado | M25: Pagado | N25: Recibido en obra
B26: =+$E$3 -> JULIETA SANTIAGO - IVAN PETRINI | C26: 45861 | D26: Fact-A-287740 | E26: PETRINI IVAN | F26: Hierros del 8, 12 y 16 | G26: Serin | H26: Obra Gruesa | I26: 3471631.1 | K26: A proveedor | L26: Pagado | M26: Pagado | N26: Recibido en obra
B27: =+$E$3 -> JULIETA SANTIAGO - IVAN PETRINI | C27: 45869 | D27: Efectivo | E27: Sin factura | F27: Acopio de aridos | G27: San Cayetano | H27: Obra Gruesa | I27: 3200000 | K27: A bauvek | L27: Pagado | M27: Pagado | N27: Acopio
B28: =+$E$3 -> JULIETA SANTIAGO - IVAN PETRINI | C28: 45877 | D28: Fact-A-287741 | E28: PETRINI IVAN | F28: 1º cuota de ENAS | G28: ENAS | H28: Obra Gruesa | I28: 4862385 | K28: A proveedor | L28: Pagado | M28: Pagado | N28: Recibido en obra
B29: =+$E$3 -> JULIETA SANTIAGO - IVAN PETRINI | C29: 45888 | D29: Efectivo | E29: Sin factura | F29: Hormigon de vigas de fundacion 10m3 mas | G29: Hormiblock | H29: Obra Gruesa | I29: 1158000 | K29: A bauvek | L29: Pagado | M29: Pagado | N29: Recibido en obra
B30: =+$E$3 -> JULIETA SANTIAGO - IVAN PETRINI | C30: 45891 | D30: Efectivo | E30: Sin factura | F30: Flete de alambron del 6 y clavos | G30: Flete Hugo Godoy | H30: Fletes | I30: 73500 | K30: A bauvek | L30: Pagado | M30: Pagado | N30: Recibido en obra
... B55: =+$E$3 -> JULIETA SANTIAGO - IVAN PETRINI | C55: 45972 | D55: Fact-A-050006 | E55: PETRINI IVAN | F55: Hormigon H25 | G55: Holcim | H55: Obra Gruesa | I55: 5227200 | K55: A proveedor | L55: Pagado | M55: Pagado | N55: Recibido en obra
B56: =+$E$3 -> JULIETA SANTIAGO - IVAN PETRINI | C56: 45986 | D56: NCA - 14156 | E56: PETRINI IVAN | F56: Devoluc. caños de cloacas y cojinetes | G56: Saniplast | H56: Instalaciones | I56: -488080 | K56: A cliente | L56: Pagado | M56: Pagado
B57: =+$E$3 -> JULIETA SANTIAGO - IVAN PETRINI | C57: 45995 | D57: Fact-A-065327 | E57: PETRINI IVAN | F57: Caño corrugado semipesado | G57: Feyro | H57: Electricidad | I57: 541000.71 | K57: A proveedor | L57: Pagado | M57: Pagado | N57: Recibido en obra
A58: Pasado quincena | C58: 45996
B59: =+$E$3 -> JULIETA SANTIAGO - IVAN PETRINI | C59: 46003 | D59: Fact-A-027601 | E59: PETRINI IVAN | F59: Tablas, fenolicos, puntales de THº PB | G59: Mendio | H59: Obra Gruesa | I59: 3751773.8 | L59: Pagado | M59: Pagado | N59: Recibido en obra
B60: =+$E$3 -> JULIETA SANTIAGO - IVAN PETRINI | C60: 46009 | D60: Fact-A-0293934 | E60: PETRINI IVAN | F60: 4 Perfiles UPN180 | G60: Serin | H60: Herreria | I60: 2612931.4 | L60: Pagado | M60: Pagado | N60: Recibido en obra
B61: =+$E$3 -> JULIETA SANTIAGO - IVAN PETRINI | D61: Efectivo | E61: Sin factura | F61: Placa de 30x30x1/2 pulgada | G61: Roncaglia | H61: Herreria | I61: 29000 | L61: Pagado | M61: Pagado | N61: Recibido en obra
B62: =+$E$3 -> JULIETA SANTIAGO - IVAN PETRINI | C62: 46003 | D62: Fact-A-003857 | E62: PETRINI IVAN | F62: Buñas | G62: Maderas Colón | H62: Obra Gruesa | I62: 74954.85 | L62: Pagado | M62: Pagado | N62: Recibido en obra
B63: =+$E$3 -> JULIETA SANTIAGO - IVAN PETRINI | C63: 46008 | D63: Fact-A-0000945 | E63: PETRINI IVAN | F63: Hormigon visto H25 Tabiques PB | G63: Pilca | H63: Hormigón | I63: 8224776.5 | L63: Pagado | M63: Pagado | N63: Pendiente
B64: =+$E$3 -> JULIETA SANTIAGO - IVAN PETRINI | C64: 46008 | D64: Fact-A-0072462 | E64: PETRINI IVAN | F64: Materiales de gas | G64: Saniplast | H64: Plomería | I64: 1846912.6 | L64: Pagado | M64: Pagado | N64: Recibido en obra
B65: =+$E$3 -> JULIETA SANTIAGO - IVAN PETRINI | C65: 46003 | D65: Fact-A-001155 | E65: PETRINI IVAN | F65: Alambron del 6, alambre de atar, clavos y alambre del 4 | G65: Hierros Industriales | H65: Obra Gruesa | I65: 1273790.2 | L65: Pagado | M65: Pagado | N65: Recibido en obra
A66: Pasado quincena | C66: 46022
B67: =+$E$3 -> JULIETA SANTIAGO - IVAN PETRINI | C67: 46035 | D67: Efectivo | E67: Sin factura | F67: Flete de alambron del 6 y chanfles | G67: Flete Hugo Godoy | H67: Fletes | I67: 95000 | K67: A bauvek | L67: Pagado | M67: Pagado | N67: Recibido en obra
A68: Pasado quincena | C68: 46037
B69: =+$E$3 -> JULIETA SANTIAGO - IVAN PETRINI | C69: 46041 | D69: Transeferencia | E69: Sin factura | F69: Flete del canguro desde Alq Todo VGB a obra | G69: Cristian Canziani | H69: Fletes | I69: 60000 | K69: A bauvek | L69: Pagado | M69: Pagado | N69: Recibido en obra
...

Sheet Obra Cañuelas
D2: GASTOS MATERIAL OBRA
D3: Cliente: | E3: OBRA GIAVENNO
D4: Domicilio: | E4: LOTE 5, MZA 17 | F4: Localidad: Zona Sur Cordoba
F5: Barrio: Cañuelas Country Golf
B9: OBRA | C9: Fecha de FC | D9: Condición | E9: Razón social | F9: Descripción | G9: Proveedor | H9: Rubro | I9: Importe final Pesos (Iva incluido) | J9: Importe final USD (Iva incluido) | K9: Observaciones | L9: Estado Factura Cliente | M9: Estado Factura Bauvek | N9: Estado material | O9: Resarcimiento Bauvek | P9: Nº Remito | Q9: Encargado
B10: =+$E$3 -> OBRA GIAVENNO | C10: 45966 | D10: FACT -A 00123 | E10: A cuenta de Bauvek | F10: Modulos ciegos Bauhaus | G10: Feyro | H10: Electricidad | I10: 5295.3 | K10: Retiro Julian por la sucursal de o´higgins | L10: Pagado | N10: Recibido en obra | O10: No Pagado
B11: =+$E$3 -> OBRA GIAVENNO | C11: 45968 | D11: FACT -A 00138 | E11: A cuenta de Bauvek | F11: Cable utp | G11: Feyro | H11: Electricidad | I11: 67820.75 | K11: Retiro Julian por la sucursal de o´higgins | L11: Pagado | N11: Recibido en obra | O11: No Pagado
B12: =+$E$3 -> OBRA GIAVENNO | C12: 45971 | D12: FACT -A 00142 | E12: A cuenta de Bauvek | F12: Tapas, bastidores, Bauhaus | G12: Feyro | H12: Electricidad | I12: 15476.44 | K12: Retiro Julian por la sucursal de o´higgins | L12: Pagado | N12: Recibido en obra | O12: No Pagado
B13: =+$E$3 -> OBRA GIAVENNO | C13: 45975 | D13: FACT -A 00161 | E13: A cuenta de Bauvek | F13: Tapas y distanciadores bauhaus | G13: Feyro | H13: Electricidad | I13: 9900 | K13: Retiro Julian por la sucursal de o´higgins | L13: Pagado | N13: Recibido en obra | O13: No Pagado
A14: Pasado quincena | C14: =+$F$3 -> 0 | D14: 45996
B15: =+$E$3 -> OBRA GIAVENNO | C15: 46006 | D15: Efectivo | E15: A cuenta de Bauvek | F15: Alquiler x 1 día de bomba sumergible | G15: Alquilo Todo | H15: Alquiler | I15: 20000 | K15: Retiró Julian por Alquilo Todo | L15: Pagado | N15: Recibido en obra
B16: =+$E$3 -> OBRA GIAVENNO | C16: 46010 | E16: A cuenta de Bauvek | F16: Pintura para retocar un problema de filtracion | G16: Pintecord | H16: Pintura | I16: 23639.46 | K16: Retiró Julian por la sucursal de la oñhiggins | L16: Pagado | N16: Recibido en obra | O16: No Pagado
A17: Pasado quincena | D17: 46022
B18: =+$E$3 -> OBRA GIAVENNO | C18: 46027 | D18: FACT -A 001503 | E18: A cuenta de Bauvek | F18: Pintura para retocar un problema de filtracion | G18: Pintecord | H18: Pintura | I18: 11436.26 | K18: Retiró Julian por la sucursal de la o´higgins camino san carlos | L18: Pagado | N18: Recibido en obra | O18: No Pagado
A19: Pasado quincena | D19: 46037
A20: Pasado quincena | C20: 46065
B21: =+$E$3 -> OBRA GIAVENNO | C21: 46051 | D21: FACT-A67132 | E21: A cuenta de Bauvek | F21: mat de electricidad | G21: Feyro | H21: Electricidad | I21: 55000.05 | L21: Pagado | N21: Recibido en obra | O21: No Pagado
A22: Pasado quincena | C22: 46079
B23: =+$E$3 -> OBRA GIAVENNO
A24: Pasado quincena | C24: 46093
B25: =+$E$3 -> OBRA GIAVENNO | C25: 46100 | D25: FACT-A 10331 | E25: Bauvek | F25: Mat pintura impermeabilizacion | G25: Garin | H25: Pintura | I25: 34483.72 | K25: Retiro Mari en gauss | L25: No Pagado | N25: Recibido en obra | O25: No Pagado
A26: Pasado quincena | C26: 46107
A27: Pasado quincena | B27: =+$E$3 -> OBRA GIAVENNO | C27: 46149
A28: Prox cierre | B28: =+$E$3 -> OBRA GIAVENNO | C28: 46163
B29: =+$E$3 -> OBRA GIAVENNO
B30: =+$E$3 -> OBRA GIAVENNO
B31: =+$E$3 -> OBRA GIAVENNO
B32: =+$E$3 -> OBRA GIAVENNO
B33: =+$E$3 -> OBRA GIAVENNO
B34: =+$E$3 -> OBRA GIAVENNO
B35: =+$E$3 -> OBRA GIAVENNO
B36: =+$E$3 -> OBRA GIAVENNO
B37: =+$E$3 -> OBRA GIAVENNO
B38: =+$E$3 -> OBRA GIAVENNO
B39: =+$E$3 -> OBRA GIAVENNO
B40: =+$E$3 -> OBRA GIAVENNO
... B51: =+$E$3 -> OBRA GIAVENNO
G53: TOTAL | H53: =SUM(I10:I51) -> 243051.98

Sheet Obra EC
D2: GASTOS MATERIAL OBRA
D3: Cliente: | E3: EMILIO CONTIGIANI
D4: Domicilio: | E4: Lote 182 | F4: Localidad: | H4: El Terron
B9: OBRA | C9: Fecha de FC | D9: Condición | E9: Razón social | F9: Descripción | G9: Proveedor | H9: Rubro | I9: Importe final Pesos (Iva incluido) | J9: Importe final USD (Iva incluido) | K9: Observaciones | L9: Estado Factura Cliente | M9: Estado Factura Bauvek | N9: Estado material | O9: Resarcimiento Bauvek | P9: Nº Remito | Q9: Encargado
B10: =+$E$3 -> EMILIO CONTIGIANI | C10: 45986 | D10: S/N | E10: Sin factura | F10: Material arreglo | G10: Pintecord | H10: Pintura | K10: Perdida | L10: Pagado | N10: Pendiente | O10: No Pagado
B11: =+$E$3 -> EMILIO CONTIGIANI | C11: 45988 | D11: S/N | E11: Sin factura | F11: Retiro/traslado de andamios de lote 364 a 182 del terron, Mendiolaza | G11: Flete Hugo Godoy | H11: Flete | I11: 60000 | K11: a Bauvek | L11: Pagado | N11: Recibido en obra | O11: No Pagado
A12: Pasado quincena | C12: 45996
B13: =+$E$3 -> EMILIO CONTIGIANI | C13: 46045 | D13: S/N | E13: Sin factura | F13: Traslado de tejas de Contigiani a obra del terron | G13: Flete Hugo Godoy | H13: Flete | I13: 45000 | K13: a Bauvek | L13: Pagado | N13: Recibido en obra | O13: No Pagado
A14: Pasado quincena | C14: 46051
A15: Prox cierre | B15: =+$E$3 -> EMILIO CONTIGIANI | C15: 46065
A16: Prox cierre | B16: =+$E$3 -> EMILIO CONTIGIANI | C16: 46079
A17: Prox cierre | B17: =+$E$3 -> EMILIO CONTIGIANI | C17: 46093
A18: Prox cierre | B18: =+$E$3 -> EMILIO CONTIGIANI | C18: 46107
A19: Pasado quincena | C19: 46135
A20: Prox cierre | B20: =+$E$3 -> EMILIO CONTIGIANI | C20: 46149
A21: Prox cierre | B21: =+$E$3 -> EMILIO CONTIGIANI | C21: 46163
B22: =+$E$3 -> EMILIO CONTIGIANI
B23: =+$E$3 -> EMILIO CONTIGIANI
B24: =+$E$3 -> EMILIO CONTIGIANI
B25: =+$E$3 -> EMILIO CONTIGIANI
B26: =+$E$3 -> EMILIO CONTIGIANI
B27: =+$E$3 -> EMILIO CONTIGIANI
B28: =+$E$3 -> EMILIO CONTIGIANI
B29: =+$E$3 -> EMILIO CONTIGIANI
B30: =+$E$3 -> EMILIO CONTIGIANI
B31: =+$E$3 -> EMILIO CONTIGIANI
B32: =+$E$3 -> EMILIO CONTIGIANI
B33: =+$E$3 -> EMILIO CONTIGIANI
... B49: =+$E$3 -> EMILIO CONTIGIANI
H51: TOTAL | I51: =SUM(I10:I49) -> 105000

Sheet Obra RR
D2: GASTOS MATERIAL OBRA
D3: Cliente: | E3: HNOS ROSSI
D4: Domicilio: | E4: LOTE 12 - MZA 59 | F4: Localidad: Villa Ciudad Parque
F5: Barrio: Molvento
B9: OBRA | C9: Fecha de FC | D9: Condición | E9: Razón social | F9: Descripción | G9: Proveedor | H9: Rubro | I9: Importe final Pesos (Iva incluido) | J9: Importe final USD (Iva incluido) | K9: Observaciones | L9: Estado Factura Cliente | M9: Estado Factura Bauvek | N9: Estado material | O9: Resarcimiento Bauvek | P9: Nº Remito | Q9: Encargado | R9: Columna1 | S9: Columna2
B10: =+$E$3 -> HNOS ROSSI | C10: 45894 | D10: Fact-A-005426 | E10: AGRICOLA MAGDALENA SRL | F10: Hierro para fundaciones | G10: Steel Brox | H10: Obra Gruesa | I10: 9416519.6 | L10: Pagado | M10: Pagado | N10: Recibido en obra
B11: =+$E$3 -> HNOS ROSSI | C11: 45898 | D11: Fact-A-014006 | E11: AGRICOLA MAGDALENA SRL | F11: Media sombra | G11: Cerroplast | H11: Obra Preliminar | I11: 420462.9 | L11: Pagado | M11: Pagado | N11: Recibido en obra
B12: =+$E$3 -> HNOS ROSSI | C12: 45903 | D12: Fact-A-025966 | E12: AGRICOLA MAGDALENA SRL | F12: Puntales para cerco | G12: Mendio | H12: Obra Preliminar | I12: 1028351.9 | L12: Pagado | M12: Pagado | N12: Recibido en obra
B13: =+$E$3 -> HNOS ROSSI | C13: 45904 | D13: Factura | E13: Bauvek | F13: Materiales para pilar de luz | G13: Feyro | H13: Obra Electrica | I13: 173752.87 | L13: Pagado | M13: Pagado | N13: Recibido en obra
B14: =+$E$3 -> HNOS ROSSI | C14: 45936 | D14: Cheque | E14: Sin factura | F14: Obrador y baño quimico x 12 meses | G14: Natalia Obrador | H14: Obra Preliminar | I14: 2740000 | L14: Pagado | M14: Pagado | N14: Recibido en obra
B15: =+$E$3 -> HNOS ROSSI | C15: 45961 | D15: Fact-A-050342 | E15: Bauvek | F15: Materiales para pico de agua | G15: Deplano | H15: Plomeria | I15: 43028.22 | K15: Pagar y desp recuperar | L15: Cuenta Corriente | N15: Recibido en obra
B16: =+$E$3 -> HNOS ROSSI | C16: 45972 | D16: Fact-A-039846 | E16: Bauvek | F16: Mat. de plomeria para PSS | G16: Deplano | H16: Plomeria | I16: 158243.85 | K16: Pagar y desp recuperar | L16: Cuenta Corriente | N16: Recibido en obra
B17: =+$E$3 -> HNOS ROSSI | C17: 45972 | D17: Fact-A-050048 | E17: AGRICOLA MAGDALENA SRL | F17: Bombeo de hormigon | G17: Holcim | H17: Obra Gruesa | I17: 401418 | L17: Pagado | M17: Pagado | N17: Recibido en obra
B18: =+$E$3 -> HNOS ROSSI | C18: 45972 | D18: Fact-A-050009 | E18: AGRICOLA MAGDALENA SRL | F18: Servicio de instalacion | G18: Holcim | H18: Obra Gruesa | I18: 280992.6 | L18: Pagado | M18: Pagado | N18: Recibido en obra
B19: =+$E$3 -> HNOS ROSSI | C19: 45972 | D19: Fact-A-050008 | E19: AGRICOLA MAGDALENA SRL | F19: Hormigon de fundaciones | G19: Holcim | H19: Obra Gruesa | I19: 3090918.6 | L19: Pagado | M19: Pagado | N19: Recibido en obra
B20: =+$E$3 -> HNOS ROSSI | C20: 45978 | D20: Fact-A-029096 | E20: AGRICOLA MAGDALENA SRL | F20: Bomba sumergible | G20: Dimotec | H20: Plomeria | I20: 230850 | L20: Pagado | M20: Pagado | N20: Recibido en obra
B21: =+$E$3 -> HNOS ROSSI | C21: 45978 | D21: Fact-A-029097 | E21: AGRICOLA MAGDALENA SRL | F21: 25 m3 de hormigon de contrapiso H17 | G21: Pilca | H21: Obra Gruesa | I21: 4722050.1 | L21: Pagado | M21: Pagado | N21: Recibido en obra
A22: Pasado quincena
B23: =+$E$3 -> HNOS ROSSI | C23: 45986 | D23: Fact-A-027348 | E23: AGRICOLA MAGDALENA SRL | F23: Puntales, tablas cepilladas y fenolicos | G23: Mendio | H23: Obra Gruesa | I23: 4426851.4 | K23: A proveedor | L23: Pagado | M23: Pagado | N23: Recibido en obra
B24: =+$E$3 -> HNOS ROSSI | C24: 45981 | D24: Fact-A-027349 | E24: AGRICOLA MAGDALENA SRL | F24: Mallas del 6 y hierros | G24: Acerco | H24: Obra Gruesa | I24: 4889683.5 | K24: A proveedor | L24: Pagado | M24: Pagado | N24: Recibido en obra
B25: =+$E$3 -> HNOS ROSSI | C25: 45994 | D25: Fact-A-006032 | E25: AGRICOLA MAGDALENA SRL | F25: Vigas Enas (1º cuota con flete) | G25: Enas | H25: Obra Gruesa | I25: 1387870 | K25: A proveedor | L25: Pagado | M25: Pagado | N25: Recibido en obra
B26: =+$E$3 -> HNOS ROSSI | C26: 45986 | D26: Fact-A-024190 | E26: AGRICOLA MAGDALENA SRL | F26: Materiales de obra gruesa | G26: Apromax | H26: Obra Gruesa | I26: 10830205 | K26: A proveedor | L26: Pagado | M26: Pagado | N26: Acopio
B27: =+$E$3 -> HNOS ROSSI | C27: 45996 | E27: Sin factura | F27: Acopio de aridos | G27: A definir | H27: Obra Gruesa | I27: 4360746.8 | K27: A bauvek | L27: Pagado
B28: =+$E$3 -> HNOS ROSSI | C28: 45994 | D28: Fact-A-014686 | E28: AGRICOLA MAGDALENA SRL | F28: Alambron del 6 y clavos de 2,5 pulgadas | G28: Hierros Industriales | H28: Obra Gruesa | I28: 795549.58 | K28: A proveedor | L28: Pagado | M28: Pagado | N28: Recibido en obra
B29: =+$E$3 -> HNOS ROSSI | C29: 45994 | D29: Fact-A-034143 | E29: AGRICOLA MAGDALENA SRL | F29: Separadores para tabiques | G29: Sinis | H29: Obra Gruesa | I29: 479755.32 | K29: A proveedor | L29: Pagado | M29: Pagado | N29: Recibido en obra
B30: =+$E$3 -> HNOS ROSSI | C30: 45994 | D30: Fact-A-065307 | E30: AGRICOLA MAGDALENA SRL | F30: Materiales de corrugado y cajas de electricidd | G30: Feyro | H30: Obra Gruesa | I30: 1140238.2 | K30: A proveedor | L30: Pagado | M30: Pagado | N30: Recibido en obra
B31: =+$E$3 -> HNOS ROSSI | C31: 45994 | D31: Fact-A-000929 | E31: AGRICOLA MAGDALENA SRL | F31: 26 m3 de H25 y 8 m3 del H21 | G31: Pilca | H31: Hormigones | I31: 7095091.7 | K31: A proveedor | L31: Pagado | M31: Pagado
A32: Pasado quincena | C32: 45996
B33: =+$E$3 -> HNOS ROSSI | C33: 45996 | D33: Fact-A | E33: Bauvek SAS | F33: mat. Plomeria para bomba pluvial - Pago david, abonarle para recuperar | G33: Saniplast | H33: Plomeria | I33: 169554.67 | K33: A bauvek | L33: Pagado | M33: Pagado | N33: Recibido en obra
B34: =+$E$3 -> HNOS ROSSI | C34: 46365 | D34: S/N | E34: S/N | F34: Retiro de Hierros industriales, Apromax, feyro (Zona Guiñazu) y Sinis circunvalacion, envio a Molvento | G34: Flete Hugo Godoy | H34: Flete | I34: 175000 | K34: A bauvek | L34: Pagado | M34: Pagado | N34: Recibido en obra
B35: =+$E$3 -> HNOS ROSSI | C35: 46008 | D35: Fact-A 6081 | E35: AGRICOLA MAGDALENA SRL | F35: 1 | G35: Enas | H35: Encofrado | I35: 896610 | K35: A proveedor | L35: Pagado | M35: Pagado | N35: Recibido en obra
A36: Pasado quincena | C36: 46009
A37: Pasado quincena | C37: 46022
B38: =+$E$3 -> HNOS ROSSI | C38: 46034 | D38: Fact-A-006421 | E38: AGRICOLA MAGDALENA SRL | F38: 8 placas metalicas 25x25 para columnas | G38: Roncaglia | H38: Plegados | I38: 184000 | K38: A proveedor | L38: Pagado | M38: Pagado | N38: Recibido en obra
B39: =+$E$3 -> HNOS ROSSI | C39: 46034 | D39: Fact-A-72762,72761,72765,72763,72764 | E39: AGRICOLA MAGDALENA SRL | F39: Materiales de agua, cloaca, pluvial y gas | G39: Saniplast | H39: Plomeria | I39: 7215137.5 | K39: A proveedor | L39: Pagado | M39: Pagado | N39: Recibido en obra
B40: =+$E$3 -> HNOS ROSSI | C40: 46034 | D40: Fact-A-00958 | E40: AGRICOLA MAGDALENA SRL | F40: Hormigon para pilotes y vigas PB | G40: Pilca | H40: Hormigon | I40: 4103527.6 | K40: A proveedor | L40: Pagado | M40: Pagado
B41: =+$E$3 -> HNOS ROSSI | C41: 46034 | D41: Fact-A-30187 | E41: AGRICOLA MAGDALENA SRL | F41: 50% de excavacion de pilotes PB | G41: Canteras El Alto | H41: Pilotes | I41: 509476.55 | K41: A proveedor | L41: Pagado | M41: Pagado | N41: Recibido en obra
B42: =+$E$3 -> HNOS ROSSI | C42: 46034 | D42: Fact-A-24358 | E42: AGRICOLA MAGDALENA SRL | F42: Hierros para pilotes y vigas fundacion PB | G42: Apromax | H42: Obra Gruesa | I42: 2908060 | K42: A proveedor | L42: Pagado | M42: Pagado | N42: Recibido en obra
B43: =+$E$3 -> HNOS ROSSI | C43: 46035 | D43: Fact-A | E43: Bauvek SAS | F43: Alquiler de 2 vibros bosh se uso en el hormigon del 22/12/2025 | G43: Alquilo Todo | H43: Alquiler | I43: 100000 | K43: A bauvek | L43: Pagado | M43: Pagado | N43: Recibido en obra
B44: =+$E$3 -> HNOS ROSSI | C44: 46035 | D44: Efectivo | E44: Sin factura | F44: Flete materiales de plomería | G44: Flete Hugo Godoy | H44: Fletes | I44: 95000 | K44: A bauvek | L44: Pagado | M44: Pagado | N44: Recibido en obra
...

Sheet Obra EM
D2: GASTOS MATERIAL OBRA
D3: Cliente: | E3: Esteban y Matias
D4: Domicilio: | E4: Mza 3 - lote 16 | F4: Localidad: | H4: La Calera
E5: Vistas de La Deseada
B9: OBRA | C9: Fecha de FC | D9: Condición | E9: Razón social | F9: Descripción | G9: Proveedor | H9: Rubro | I9: Importe final Pesos (Iva incluido) | J9: Importe final USD (Iva incluido) | K9: Observaciones | L9: Estado Factura Cliente | M9: Estado Factura Bauvek | N9: Estado material | O9: Resarcimiento Bauvek | P9: Nº Remito | Q9: Encargado | R9: Columna1
B10: =+$E$3 -> Esteban y Matias | C10: 46125 | D10: s/n | E10: Sin factura | F10: 50% pago anticipo de moviemiento de suelo | G10: Pellicer | H10: Mov. Suelo | I10: 19250000 | K10: A bauvek | L10: Pagado | M10: Pagado | N10: Recibido en obra
A11: Pasado quincena | B11: =+$E$3 -> Esteban y Matias | C11: 46121
B12: =+$E$3 -> Esteban y Matias | C12: 46133 | D12: s/n | E12: Sin factura | F12: media sombra, alambre galvanizado | G12: Cerroplast | H12: cerco obra | I12: 710063 | K12: A bauvek | L12: Pagado | M12: Pagado | N12: Recibido en obra
B13: =+$E$3 -> Esteban y Matias | C13: 46133 | D13: s/n | E13: Sin factura | F13: Puntales de madera y tablas para corralito | G13: Mendio SA | H13: cerco obra | I13: 914394.4 | K13: A bauvek | L13: Pagado | M13: Pagado | N13: Recibido en obra
B14: =+$E$3 -> Esteban y Matias | C14: 46133 | D14: s/n | E14: Sin factura | F14: Baño quimico y obrador por 6 meses | G14: Conte Mas | H14: Obrador | I14: 710000 | K14: A bauvek | L14: Pagado | M14: Pagado | N14: Recibido en obra
A15: Pasado quincena | B15: =+$E$3 -> Esteban y Matias
B16: =+$E$3 -> Esteban y Matias | C16: 46147 | D16: Fact | E16: consumidor final | F16: Material pilar de luz | G16: Feyro | H16: pilar luz | I16: 255983.44 | K16: a proveedor | L16: Pagado | M16: Pagado | N16: Recibido en obra
B17: =+$E$3 -> Esteban y Matias | C17: 46147 | D17: Fact | E17: consumidor final | F17: Material cerco obra | G17: Acerco | H17: cerco obra | I17: 605305.09 | K17: a proveedor | L17: Pagado | M17: Pagado | N17: Recibido en obra
B18: =+$E$3 -> Esteban y Matias | C18: 46147 | D18: Fact | E18: consumidor final | F18: Material canilla | G18: Deplano | H18: canilla | I18: 15956.44 | K18: a proveedor | L18: Pagado | M18: Pagado | N18: Recibido en obra
A19: Pasado quincena | B19: =+$E$3 -> Esteban y Matias | C19: 46149
B20: =+$E$3 -> Esteban y Matias | C20: 46162 | D20: s/n | E20: Sin factura | F20: Hierros fundacion y arena | G20: Merlino | H20: obra gruesa | I20: 3619700 | K20: a proveedor | L20: Pagado | M20: Pagado | N20: Pendiente
B21: =+$E$3 -> Esteban y Matias | C21: 46163 | D21: Fact | E21: consumidor final | F21: proyector solar ABS 800ml 5700K luz fria + panel solar | G21: Feyro | H21: iluminacion | I21: 43724.11 | K21: A bauvek | L21: Pagado | M21: Pagado | N21: Recibido en obra
B22: =+$E$3 -> Esteban y Matias | C22: 46154 | D22: s/n | E22: Sin factura | F22: Carga en Cerroplast, Deplano, Feyro, taller del herrero | G22: Flete Hugo Godoy | H22: flete | I22: 120000 | K22: A bauvek | L22: Pagado | M22: Pagado | N22: Recibido en obra
A23: Pasado quincena | B23: =+$E$3 -> Esteban y Matias | C23: 46163
A24: Pasado quincena | B24: =+$E$3 -> Esteban y Matias | C24: 46177
B25: =+$E$3 -> Esteban y Matias | C25: 46178 | D25: s/n | E25: Sin factura | F25: Acopio de H° fundaciones y tabiques hasta planta subsuelo | G25: Hormiblock | H25: Hormigon | I25: 22416250 | K25: A bauvek | L25: Pagado | M25: Pagado | N25: Recibido en obra
B26: =+$E$3 -> Esteban y Matias | C26: 46178 | D26: s/n | E26: Sin factura | F26: Materiales obra gruesa fundaciones | G26: Apromax | H26: obra gruesa | I26: 9444594.1 | K26: A bauvek | L26: Pagado | M26: Pagado | N26: Recibido en obra
B27: =+$E$3 -> Esteban y Matias
A28: Pasado quincena | B28: =+$E$3 -> Esteban y Matias | C28: 46191
B29: =+$E$3 -> Esteban y Matias | C29: 46199 | D29: s/n | E29: Sin factura | F29: Traslado de material de SINIS a vistas de la deseada | G29: Flete Jonatan | H29: flete | I29: 200000 | K29: A bauvek | L29: Pagado | M29: Pagado | N29: Recibido en obra
B30: =+$E$3 -> Esteban y Matias | C30: 46199 | D30: s/n | E30: Sin factura | F30: Traslado de material de SINIS a vistas de la deseada | G30: Flete Jonatan | H30: flete | I30: 200000 | K30: A bauvek | L30: Pagado | M30: Pagado | N30: Recibido en obra
B31: =+$E$3 -> Esteban y Matias
A32: Pasado quincena | B32: =+$E$3 -> Esteban y Matias | C32: 46205
B33: =+$E$3 -> Esteban y Matias | C33: 46211 | D33: S/N | E33: Sin factura | F33: Flete de tablas de madera de obra JS a obra | G33: Flete Gonza Moreno | H33: Fletes | I33: 200000 | K33: A Bauvek | L33: No Pagado | M33: No Pagado | N33: Recibido en obra
B34: =+$E$3 -> Esteban y Matias | C34: 46211 | D34: S/N | E34: Sin factura | F34: Flete de fenolicos a obra | G34: Flete Hugo Godoy | H34: flete | I34: 70000 | K34: A Bauvek | L34: No Pagado | M34: No Pagado | N34: Recibido en obra
B35: =+$E$3 -> Esteban y Matias | C35: 46205 | D35: Fact 29008 | E35: bauvek | F35: Cuñas y buñas a cuenta de bauvek | G35: Mendio SA | H35: material | I35: 368917.65 | K35: a proveedor | L35: No Pagado | M35: No Pagado | N35: Recibido en obra
B36: =+$E$3 -> Esteban y Matias | C36: 46210 | D36: Fact 29058 | E36: Bauvek | F36: Fenolicos a cuenta de bauvek | G36: Mendio SA | H36: material | I36: 325000.25 | K36: a proveedor | L36: No Pagado | M36: No Pagado | N36: Recibido en obra
A37: Pasado quincena | B37: =+$E$3 -> Esteban y Matias | C37: 46219
B38: =+$E$3 -> Esteban y Matias | C38: 46223 | D38: S/N | E38: Sin factura | F38: Devolucion de material en alquiler SINIS | G38: Flete Fede Castro | H38: flete | I38: 170000 | K38: A Bauvek | L38: Pagado | M38: Pagado | N38: Recibido en obra
B39: =+$E$3 -> Esteban y Matias | C39: 46224 | D39: S/N | E39: Sin factura | F39: Devolucion de material en alquiler SINIS | G39: Flete Fede Castro | H39: flete | I39: 170000 | K39: A Bauvek | L39: Pagado | M39: Pagado | N39: Recibido en obra
B40: =+$E$3 -> Esteban y Matias | C40: 46218 | D40: Fact 2004 | E40: Bauvek | F40: Perfiles metalicos | G40: Serin | H40: perfiles | I40: 2350729.1 | K40: A Bauvek | L40: Pagado | M40: No Pagado | N40: Recibido en obra
B41: =+$E$3 -> Esteban y Matias | D41: nota de credito | E41: Bauvek | F41: Perfiles metalicos | G41: Serin | H41: nota de credito | I41: -43692 | K41: A Bauvek | L41: No Pagado | M41: No Pagado | N41: Recibido en obra
B42: =+$E$3 -> Esteban y Matias | C42: 46230 | D42: S/N | E42: Sin factura | F42: Granza 1.3 | G42: Merlino | H42: aridos | I42: 319803 | K42: A Bauvek | L42: Pagado | M42: Pagado | N42: Recibido en obra
B43: =+$E$3 -> Esteban y Matias | C43: 46231 | D43: S/N | E43: Sin factura | F43: Fenolicos, buñas, | G43: Mendio SA | H43: material | K43: A Bauvek | L43: Pagado | M43: No Pagado | N43: Recibido en obra
B44: =+$E$3 -> Esteban y Matias | C44: 46231 | D44: S/N | E44: Sin factura | F44: Puntales | G44: Mendio SA | H44: material | I44: 542491.2 | K44: A Bauvek | L44: Pagado | M44: Pagado | N44: Recibido en obra
...

Sheet Obra LS
D2: GASTOS MATERIAL OBRA
D3: Cliente: | E3: Rodolfo Subias y Melisa Lew
D4: Domicilio: | E4: Lote 364 | F4: Localidad: | H4: El terrón, Mendiolaza
B9: OBRA | C9: Fecha de FC | D9: Condición | E9: Razón social | F9: Descripción | G9: Proveedor | H9: Rubro | I9: Importe final Pesos (Iva incluido) | J9: Importe final USD (Iva incluido) | K9: Observaciones | L9: Estado Factura Cliente | M9: Estado Factura Bauvek | N9: Estado material | O9: Resarcimiento Bauvek | P9: Nº Remito | Q9: Encargado
B10: =+$E$3 -> Rodolfo Subias y Melisa Lew | C10: 45979 | D10: Fact B | E10: Rodolfo Subias | F10: 1 caja de porcellanato baño PA para guarda | G10: Ferrocons | H10: Terminación int | I10: 47173.87 | L10: Pagado | N10: Recibido en obra
B11: =+$E$3 -> Rodolfo Subias y Melisa Lew | C11: 45979 | D11: Fact A | E11: Bauvek | F11: 1 caja de porcellanato por rotura en baño PA | G11: Ferrocons | H11: Terminación int | I11: 48343.47 | K11: Perdida | L11: Pagado | N11: Recibido en obra | O11: Pagado
B12: =+$E$3 -> Rodolfo Subias y Melisa Lew | C12: 45979 | D12: Fact B | E12: Rodolfo Subias | F12: Materiales plomeria pluvial | G12: Saniplast | H12: Ints. Pluvial | I12: 600778.52 | K12: a proveedor | L12: Pagado | N12: Recibido en obra
B13: =+$E$3 -> Rodolfo Subias y Melisa Lew | C13: 45979 | D13: Fact B | E13: Rodolfo Subias | F13: Mat. Pintura parte metalica | G13: Garin | H13: Mat. Pintura | I13: 264716.03 | K13: a proveedor | L13: Pagado | N13: Recibido en obra
B14: =+$E$3 -> Rodolfo Subias y Melisa Lew | C14: 45979 | D14: S/N | F14: Retiro de Acerco, Ferrocons,Garin, Saniplast al terrón | G14: Flete Hugo Godoy | H14: Flete | I14: 125000 | L14: Pagado | N14: Recibido en obra
A15: Pasado quincena
B16: =+$E$3 -> Rodolfo Subias y Melisa Lew | C16: 45996 | D16: Fact A | E16: Rodolfo Subias | F16: Mat. Pegamento/pastina | G16: Contigiani | H16: Mat. Obra gruesa | I16: 1680775.1 | K16: a proveedor | L16: Pagado | N16: Recibido en obra
B17: =+$E$3 -> Rodolfo Subias y Melisa Lew | C17: 45993 | D17: S/N | E17: - | F17: ACERCO-CONTIGIANI al lote 364 | G17: Flete Hugo Godoy | H17: Flete | I17: 80000 | K17: a Bauvek | L17: Pagado | N17: Recibido en obra
B18: =+$E$3 -> Rodolfo Subias y Melisa Lew | C18: 45995 | D18: S/N | E18: - | F18: 1 viaje de arena gruesa (ya pagado cliente a Bauvek) | G18: Nico Carusso | H18: Aridos | I18: 140000 | K18: a Bauvek | L18: Pagado | N18: Recibido en obra
A19: Pasado quincena | C19: 45996
B20: =+$E$3 -> Rodolfo Subias y Melisa Lew | C20: 46009 | D20: S/N | E20: - | F20: 1 viaje de arena gruesa (ya pagado cliente a Bauvek) | G20: Nico Carusso | H20: Aridos | I20: 140000 | K20: a Bauvek | L20: Pagado | N20: Recibido en obra
A21: Pasado quincena | C21: 46009
A22: Pasado quincena | C22: 46022
B23: =+$E$3 -> Rodolfo Subias y Melisa Lew | C23: 45984 | D23: S/N | F23: Retiro de jack srl al terron (material durlock) | G23: Flete Hugo Godoy | H23: Flete | I23: 68000 | K23: a Bauvek | L23: Pagado | N23: Recibido en obra
A24: Pasado quincena | C24: 46037
B25: =+$E$3 -> Rodolfo Subias y Melisa Lew | C25: 46036 | D25: S/N | F25: Retiro de ACERCO a taller de herrero en villa allende | G25: Flete Hugo Godoy | H25: Flete | I25: 35000 | K25: a Bauvek | L25: Pagado | N25: Recibido en obra
B26: =+$E$3 -> Rodolfo Subias y Melisa Lew | C26: 46048 | D26: S/N | F26: Devolucion de andamios del terron a GUATICOR | G26: Flete Hugo Godoy | H26: Flete | I26: 54000 | K26: a Bauvek | L26: Pagado | N26: Recibido en obra
B27: =+$E$3 -> Rodolfo Subias y Melisa Lew | C27: 46048 | D27: S/N | F27: 1 contenedor de obra | G27: Contenedores Fer | H27: Flete | I27: 145000 | K27: a Bauvek | L27: Pagado | N27: Recibido en obra
B28: =+$E$3 -> Rodolfo Subias y Melisa Lew | C28: 46050 | D28: S/N | F28: 1 contenedor de obra | G28: Contenedores Fer | H28: Flete | I28: 145000 | K28: a Bauvek | L28: Pagado | N28: Recibido en obra
A29: Pasado quincena | C29: 46051
B30: =+$E$3 -> Rodolfo Subias y Melisa Lew | C30: 46052 | D30: S/N | F30: 1 contenedor de obra | G30: Contenedores Fer | H30: Flete | I30: 145000 | K30: a Bauvek | L30: Pagado | N30: Recibido en obra
B31: =+$E$3 -> Rodolfo Subias y Melisa Lew | C31: 46056 | D31: S/N | F31: 1 contenedor de obra | G31: Contenedores Fer | H31: Flete | I31: 145000 | K31: a proveedor | M31: Pagado | N31: Recibido en obra
B32: =+$E$3 -> Rodolfo Subias y Melisa Lew | C32: 46063 | D32: S/N | F32: 1 contenedor de obra | G32: Contenedores Fer | H32: Flete | I32: 145000 | K32: a proveedor | M32: Pagado | N32: Recibido en obra
A33: Pasado quincena | C33: 46065
B34: =+$E$3 -> Rodolfo Subias y Melisa Lew | C34: 46071 | D34: S/N | F34: 1 contenedor de obra | G34: Contenedores Fer | H34: Flete | I34: 150000 | K34: a proveedor | M34: Pagado | N34: Recibido en obra
B35: =+$E$3 -> Rodolfo Subias y Melisa Lew | C35: 46071 | D35: S/N | F35: 7 m3 de arena gruesa | G35: Boccolini | H35: aridos | I35: 187500 | K35: a proveedor | M35: Pagado | N35: Recibido en obra
B36: =+$E$3 -> Rodolfo Subias y Melisa Lew | C36: 46073 | D36: S/N | F36: 1 contenedor de obra | G36: Contenedores Fer | H36: Flete | I36: 150000 | K36: a proveedor | M36: Pagado | N36: Recibido en obra
B37: =+$E$3 -> Rodolfo Subias y Melisa Lew | C37: 46083 | D37: S/N | F37: 1 contenedor de obra | G37: Contenedores Fer | H37: Flete | I37: 150000 | K37: a proveedor | M37: Pagado | N37: Recibido en obra
B38: =+$E$3 -> Rodolfo Subias y Melisa Lew | C38: 46078 | D38: Fact | E38: vintage sa | F38: pegamentos | G38: Contigini | H38: Mat. Obra gruesa | M38: Pagado | N38: Pendiente
B39: =+$E$3 -> Rodolfo Subias y Melisa Lew | C39: 46078 | D39: S/N | F39: Mat de agua | G39: Saniplats | H39: Mat. Plomeria | M39: Pagado | N39: Pendiente
B40: =+$E$3 -> Rodolfo Subias y Melisa Lew | C40: 46078 | E40: vintage sa | F40: Angulos borde pileta | G40: Cyplo | H40: Herreria | K40: a Bauvek | L40: Pagado | M40: Pagado | N40: Pendiente
A41: Pasado quincena | C41: 46079
B42: =+$E$3 -> Rodolfo Subias y Melisa Lew | C42: 46084 | D42: S/N | F42: 50% manos de obra y materiales | G42: Dimotec | H42: Mat. Bombas hidrau. | I42: 4773 | K42: a proveedor | M42: Pagado | N42: Recibido en obra
B43: =+$E$3 -> Rodolfo Subias y Melisa Lew | C43: 46092 | D43: S/N | F43: 1 contenedor de obra | G43: Contenedores Fer | H43: Flete | I43: 150000 | K43: a proveedor | M43: Pagado | N43: Recibido en obra
A44: Pasado quincena | C44: 46093
B45: =+$E$3 -> Rodolfo Subias y Melisa Lew | C45: 46106 | D45: S/N | F45: 1 contenedor de obra | G45: Contenedores Fer | H45: Flete | I45: 150000 | K45: a proveedor | M45: Pagado | N45: Recibido en obra
...

Sheet Obra RL
D2: GASTOS MATERIAL OBRA
D3: Cliente: | E3: RODRIGO LUGON
D4: Domicilio: | E4: Lote 426 | F4: Localidad: | H4: Estancia Q2
B9: OBRA | C9: Fecha de FC | D9: Condición | E9: Razón social | F9: Descripción | G9: Proveedor | H9: Rubro | I9: Importe final Pesos (Iva incluido) | J9: Importe final USD (Iva incluido) | K9: Observaciones | L9: Estado Factura Cliente | M9: Estado Factura Bauvek | N9: Estado material | O9: Resarcimiento Bauvek | P9: Nº Remito | Q9: Encargado
B10: =+$E$3 -> RODRIGO LUGON | C10: 46096 | D10: Fact-A | E10: Bauvek | G10: Guaticor | H10: Alquiler | I10: 250000 | K10: a Bauvek | L10: No Pagado | N10: Recibido en obra
B11: =+$E$3 -> RODRIGO LUGON | C11: 46107 | D11: Fact-A | E11: El gran Ombu | F11: 1 contenedor | G11: Conte Top | H11: Alquiler | I11: 150000 | K11: A proveedor | L11: No Pagado | N11: Recibido en obra
A12: Pasado quincena
B13: =+$E$3 -> RODRIGO LUGON | C13: 46127 | D13: Fact-A | E13: Bauvek | G13: Guaticor | H13: Alquiler | I13: 250000 | K13: a Bauvek | L13: No Pagado | N13: Recibido en obra
A14: Pasado quincena | C14: 46135
B15: =+$E$3 -> RODRIGO LUGON | C15: 46141 | D15: Fact-A | E15: Bauvek | G15: Guaticor | H15: Alquiler | I15: 105400 | K15: a Bauvek | L15: No Pagado | N15: Recibido en obra
A16: Pasado quincena | B16: =+$E$3 -> RODRIGO LUGON | C16: 46149
B17: =+$E$3 -> RODRIGO LUGON | C17: 46175 | D17: Fact-A | E17: Gran ombu | F17: 1 contenedor | G17: Conte Top | K17: A proveedor | L17: No Pagado | N17: Recibido en obra
B18: =+$E$3 -> RODRIGO LUGON | C18: 46182 | D18: Fact-A | E18: Gran ombu | F18: 1 contenedor | G18: Conte Top | K18: A proveedor | L18: No Pagado | N18: Recibido en obra
B19: =+$E$3 -> RODRIGO LUGON
B20: =+$E$3 -> RODRIGO LUGON
A21: Pasado quincena | B21: =+$E$3 -> RODRIGO LUGON | C21: 46191
B22: =+$E$3 -> RODRIGO LUGON | C22: 46196 | D22: s/n | F22: Andamios de obra a guaticor | G22: Flete Hugo Godoy | H22: flete | I22: 75000 | K22: A proveedor | L22: No Pagado | N22: Recibido en obra
B23: =+$E$3 -> RODRIGO LUGON | C23: 46197 | D23: s/n | F23: Andamios de obra a guaticor | G23: Flete Hugo Godoy | H23: flete | I23: 75000 | K23: A proveedor | L23: No Pagado | N23: Recibido en obra
B24: =+$E$3 -> RODRIGO LUGON
B25: =+$E$3 -> RODRIGO LUGON
A26: Pasado quincena | B26: =+$E$3 -> RODRIGO LUGON | C26: 46205
B27: =+$E$3 -> RODRIGO LUGON | C27: 46244 | D27: S/N | E27: Bauvek | F27: Desplazamiento de andamios del terron a Q2 | G27: Flete Hugo Godoy | H27: flete | I27: 65000 | K27: A proveedor | L27: No Pagado | N27: Recibido en obra
A28: Pasado quincena | B28: =+$E$3 -> RODRIGO LUGON | C28: 46261
B29: =+$E$3 -> RODRIGO LUGON
B30: =+$E$3 -> RODRIGO LUGON
B31: =+$E$3 -> RODRIGO LUGON
B32: =+$E$3 -> RODRIGO LUGON
B33: =+$E$3 -> RODRIGO LUGON
A34: Prox cierre | B34: =+$E$3 -> RODRIGO LUGON | C34: 46275
B35: =+$E$3 -> RODRIGO LUGON
B36: =+$E$3 -> RODRIGO LUGON
B37: =+$E$3 -> RODRIGO LUGON
B38: =+$E$3 -> RODRIGO LUGON
B39: =+$E$3 -> RODRIGO LUGON
B40: =+$E$3 -> RODRIGO LUGON
B41: =+$E$3 -> RODRIGO LUGON
B42: =+$E$3 -> RODRIGO LUGON
B43: =+$E$3 -> RODRIGO LUGON
B44: =+$E$3 -> RODRIGO LUGON
B45: =+$E$3 -> RODRIGO LUGON
...

Sheet Obra Bauvek(NE)
D2: GASTOS MATERIAL OBRA
D3: Cliente: | E3: NE | F3: Gastos Bauvek
D4: Domicilio: | F4: Localidad:
B9: OBRA | C9: Fecha de FC | D9: Condición | E9: Razón social | F9: Descripción | G9: Proveedor | H9: Rubro | I9: Importe final Pesos (Iva incluido) | J9: Importe final USD (Iva incluido) | K9: Observaciones | L9: Estado Factura Cliente | M9: Estado Factura Bauvek | N9: Estado material | O9: Resarcimiento Bauvek | P9: Nº Remito | Q9: Encargado | R9: Columna1
B10: =+$E$3 -> NE | C10: 45993 | D10: S/N | E10: - | F10: Retiro/traslado de tierra a chacras la villa | G10: Flete Hugo Godoy | H10: Flete | I10: 50000 | K10: a Bauvek | L10: Pagado | N10: Recibido en obra
A11: Pasado quincena
B12: =+$E$3 -> NE | C12: 46017 | D12: S/N | E12: - | F12: Retiro/traslado de sillas Lucho a chacras la villa | G12: Flete Hugo Godoy | H12: Flete | I12: 80000 | K12: a Bauvek | L12: Pagado | N12: Recibido en obra
A13: Pasado quincena | C13: 46022
A14: Pasado quincena | C14: 46037
B15: =+$E$3 -> NE | C15: 46043 | D15: FACT A28027 | E15: Bauvek | F15: Material madera | G15: Mendio SA | H15: materiales | I15: 101642.26 | K15: A Bauvek | L15: Pagado | R15: Echeq a 30 días, ver cuando se emite
A16: Pasado quincena | C16: 46051
A17: Pasado quincena | C17: 46065
B18: =+$E$3 -> NE
A19: Pasado quincena | C19: 46079
B20: =+$E$3 -> NE | C20: 46079 | D20: S/N | E20: - | F20: Perfiles y tornillos | G20: Jack SRL | H20: Materiales | I20: 116099.45 | K20: A Bauvek | L20: Pagado | N20: Recibido en obra
A21: Pasado quincena | C21: 46093
A22: Pasado quincena | C22: 46107
A23: Pasado quincena | C23: 46121
B24: =+$E$3 -> NE
A25: Pasado quincena | C25: 46135
B26: =+$E$3 -> NE | C26: 46136 | D26: S/N | F26: ROLLO FILM NEGRO 3 X 50 MTS 200 MIC | G26: Jack SRL | I26: 73239.49 | K26: A Bauvek | L26: No Pagado | M26: No Pagado | N26: Recibido en obra | O26: Cuenta Corriente | R26: Para obra Emilio contigiani
